2014-02-16 15:32:23,188 : DEBUG ::: ==============================
2014-02-16 15:32:23,188 : DEBUG ::: Error occured on line 256 in file /home/konrad/.venv/sub_rosa/main/views.py
2014-02-16 15:32:23,188 : DEBUG ::: Message: Error writing to database
2014-02-16 15:32:23,188 : DEBUG ::: Details:
2014-02-16 15:32:23,188 : DEBUG ::: --------
2014-02-16 15:32:23,188 : DEBUG ::: Type: <type 'exceptions.NameError'>
2014-02-16 15:32:23,188 : DEBUG ::: Value: global name 'thumbnail' is not defined
2014-02-16 15:32:23,189 : DEBUG ::: Traceback: <traceback object at 0x2ec61b8>
2014-02-16 17:32:16,915 : DEBUG ::: ==============================
2014-02-16 17:32:16,915 : DEBUG ::: Error occured on line 254 in file /home/konrad/.venv/sub_rosa/main/views.py
2014-02-16 17:32:16,915 : DEBUG ::: Message: Error occured while processing the image
2014-02-16 17:32:16,915 : DEBUG ::: Details:
2014-02-16 17:32:16,915 : DEBUG ::: --------
2014-02-16 17:32:16,915 : DEBUG ::: Type: <type 'exceptions.IOError'>
2014-02-16 17:32:16,915 : DEBUG ::: Value: [Errno 2] No such file or directory: u'/home/konrad/.venv/sub_rosa/uploads/konrad/showcase/a_fri__by_pklklmike-d5xfv3s.showcase.jpg'
2014-02-16 17:32:16,915 : DEBUG ::: Traceback: <traceback object at 0x7f56241849e0>
2014-02-16 17:32:17,010 : DEBUG ::: ==============================
2014-02-16 17:32:17,010 : DEBUG ::: ==============================
2014-02-16 17:32:17,010 : DEBUG ::: Error occured on line 254 in file /home/konrad/.venv/sub_rosa/main/views.py
2014-02-16 17:32:17,010 : DEBUG ::: Error occured on line 254 in file /home/konrad/.venv/sub_rosa/main/views.py
2014-02-16 17:32:17,010 : DEBUG ::: Message: Error occured while processing the image
2014-02-16 17:32:17,010 : DEBUG ::: Message: Error occured while processing the image
2014-02-16 17:32:17,010 : DEBUG ::: Details:
2014-02-16 17:32:17,010 : DEBUG ::: Details:
2014-02-16 17:32:17,010 : DEBUG ::: --------
2014-02-16 17:32:17,010 : DEBUG ::: --------
2014-02-16 17:32:17,010 : DEBUG ::: Type: <type 'exceptions.IOError'>
2014-02-16 17:32:17,010 : DEBUG ::: Type: <type 'exceptions.IOError'>
2014-02-16 17:32:17,010 : DEBUG ::: Value: [Errno 2] No such file or directory: u'/home/konrad/.venv/sub_rosa/uploads/konrad/showcase/a_fri__by_pklklmike-d5xfv3s.showcase.jpg'
2014-02-16 17:32:17,010 : DEBUG ::: Value: [Errno 2] No such file or directory: u'/home/konrad/.venv/sub_rosa/uploads/konrad/showcase/a_fri__by_pklklmike-d5xfv3s.showcase.jpg'
2014-02-16 17:32:17,010 : DEBUG ::: Traceback: <traceback object at 0x2cfe050>
2014-02-16 17:32:17,010 : DEBUG ::: Traceback: <traceback object at 0x2cfe050>
2014-02-16 17:32:25,381 : DEBUG ::: ==============================
2014-02-16 17:32:25,381 : DEBUG ::: ==============================
2014-02-16 17:32:25,381 : DEBUG ::: ==============================
2014-02-16 17:32:25,381 : DEBUG ::: Error occured on line 254 in file /home/konrad/.venv/sub_rosa/main/views.py
2014-02-16 17:32:25,381 : DEBUG ::: Error occured on line 254 in file /home/konrad/.venv/sub_rosa/main/views.py
2014-02-16 17:32:25,381 : DEBUG ::: Error occured on line 254 in file /home/konrad/.venv/sub_rosa/main/views.py
2014-02-16 17:32:25,381 : DEBUG ::: Message: Error occured while processing the image
2014-02-16 17:32:25,381 : DEBUG ::: Message: Error occured while processing the image
2014-02-16 17:32:25,381 : DEBUG ::: Message: Error occured while processing the image
2014-02-16 17:32:25,381 : DEBUG ::: Details:
2014-02-16 17:32:25,381 : DEBUG ::: Details:
2014-02-16 17:32:25,381 : DEBUG ::: Details:
2014-02-16 17:32:25,381 : DEBUG ::: --------
2014-02-16 17:32:25,381 : DEBUG ::: --------
2014-02-16 17:32:25,381 : DEBUG ::: --------
2014-02-16 17:32:25,381 : DEBUG ::: Type: <type 'exceptions.IOError'>
2014-02-16 17:32:25,381 : DEBUG ::: Type: <type 'exceptions.IOError'>
2014-02-16 17:32:25,381 : DEBUG ::: Type: <type 'exceptions.IOError'>
2014-02-16 17:32:25,382 : DEBUG ::: Value: [Errno 2] No such file or directory: u'/home/konrad/.venv/sub_rosa/uploads/konrad/showcase/flux_by_imorawetz-d53bu3z.showcase.jpg'
2014-02-16 17:32:25,382 : DEBUG ::: Value: [Errno 2] No such file or directory: u'/home/konrad/.venv/sub_rosa/uploads/konrad/showcase/flux_by_imorawetz-d53bu3z.showcase.jpg'
2014-02-16 17:32:25,382 : DEBUG ::: Value: [Errno 2] No such file or directory: u'/home/konrad/.venv/sub_rosa/uploads/konrad/showcase/flux_by_imorawetz-d53bu3z.showcase.jpg'
2014-02-16 17:32:25,382 : DEBUG ::: Traceback: <traceback object at 0x2cfe758>
2014-02-16 17:32:25,382 : DEBUG ::: Traceback: <traceback object at 0x2cfe758>
2014-02-16 17:32:25,382 : DEBUG ::: Traceback: <traceback object at 0x2cfe758>
2014-02-16 17:46:54,071 : DEBUG ::: ==============================
2014-02-16 17:46:54,071 : DEBUG ::: Error occured on line 256 in file /home/konrad/.venv/sub_rosa/main/views.py
2014-02-16 17:46:54,071 : DEBUG ::: Message: Error writing to database
2014-02-16 17:46:54,071 : DEBUG ::: Details:
2014-02-16 17:46:54,071 : DEBUG ::: --------
2014-02-16 17:46:54,071 : DEBUG ::: Type: <class 'sqlalchemy.exc.IntegrityError'>
2014-02-16 17:46:54,072 : DEBUG ::: Value: (IntegrityError) UNIQUE constraint failed: user_images.filename u'INSERT INTO user_images (filename, showcase, description, is_vertical, gallery, owner_id) VALUES (?, ?, ?, ?, ?, ?)' (u'konrad/flux_by_imorawetz-d53bu3z.jpg', u'konrad/showcase/flux_by_imorawetz-d53bu3z.showcase.jpg', None, 0, 0, 1)
2014-02-16 17:46:54,072 : DEBUG ::: Traceback: <traceback object at 0x30a4d88>
2014-02-16 17:53:59,265 : DEBUG ::: ==============================
2014-02-16 17:53:59,266 : DEBUG ::: Error occured on line 256 in file /home/konrad/.venv/sub_rosa/main/views.py
2014-02-16 17:53:59,266 : DEBUG ::: Message: Error writing to database
2014-02-16 17:53:59,266 : DEBUG ::: Details:
2014-02-16 17:53:59,266 : DEBUG ::: --------
2014-02-16 17:53:59,266 : DEBUG ::: Type: <class 'sqlalchemy.exc.IntegrityError'>
2014-02-16 17:53:59,266 : DEBUG ::: Value: (IntegrityError) UNIQUE constraint failed: user_images.filename u'INSERT INTO user_images (filename, showcase, description, is_vertical, gallery, owner_id) VALUES (?, ?, ?, ?, ?, ?)' (u'konrad/mount-vesuvius-in-eruption-1817.jpg', u'konrad/showcase/mount-vesuvius-in-eruption-1817.showcase.jpg', None, 0, 0, 1)
2014-02-16 17:53:59,266 : DEBUG ::: Traceback: <traceback object at 0x7fc2cc080ef0>
2014-02-16 17:54:57,560 : DEBUG ::: ==============================
2014-02-16 17:54:57,560 : DEBUG ::: ==============================
2014-02-16 17:54:57,560 : DEBUG ::: Error occured on line 256 in file /home/konrad/.venv/sub_rosa/main/views.py
2014-02-16 17:54:57,560 : DEBUG ::: Error occured on line 256 in file /home/konrad/.venv/sub_rosa/main/views.py
2014-02-16 17:54:57,560 : DEBUG ::: Message: Error writing to database
2014-02-16 17:54:57,560 : DEBUG ::: Message: Error writing to database
2014-02-16 17:54:57,560 : DEBUG ::: Details:
2014-02-16 17:54:57,560 : DEBUG ::: Details:
2014-02-16 17:54:57,560 : DEBUG ::: --------
2014-02-16 17:54:57,560 : DEBUG ::: --------
2014-02-16 17:54:57,560 : DEBUG ::: Type: <class 'sqlalchemy.exc.IntegrityError'>
2014-02-16 17:54:57,560 : DEBUG ::: Type: <class 'sqlalchemy.exc.IntegrityError'>
2014-02-16 17:54:57,560 : DEBUG ::: Value: (IntegrityError) UNIQUE constraint failed: user_images.filename u'INSERT INTO user_images (filename, showcase, description, is_vertical, gallery, owner_id) VALUES (?, ?, ?, ?, ?, ?)' (u'konrad/mount-vesuvius-in-eruption-1817.jpg', u'konrad/showcase/mount-vesuvius-in-eruption-1817.showcase.jpg', None, 0, 0, 1)
2014-02-16 17:54:57,560 : DEBUG ::: Value: (IntegrityError) UNIQUE constraint failed: user_images.filename u'INSERT INTO user_images (filename, showcase, description, is_vertical, gallery, owner_id) VALUES (?, ?, ?, ?, ?, ?)' (u'konrad/mount-vesuvius-in-eruption-1817.jpg', u'konrad/showcase/mount-vesuvius-in-eruption-1817.showcase.jpg', None, 0, 0, 1)
2014-02-16 17:54:57,560 : DEBUG ::: Traceback: <traceback object at 0x7fc2cc08d200>
2014-02-16 17:54:57,560 : DEBUG ::: Traceback: <traceback object at 0x7fc2cc08d200>
2014-02-16 17:54:57,716 : DEBUG ::: ==============================
2014-02-16 17:54:57,716 : DEBUG ::: ==============================
2014-02-16 17:54:57,716 : DEBUG ::: ==============================
2014-02-16 17:54:57,716 : DEBUG ::: Error occured on line 256 in file /home/konrad/.venv/sub_rosa/main/views.py
2014-02-16 17:54:57,716 : DEBUG ::: Error occured on line 256 in file /home/konrad/.venv/sub_rosa/main/views.py
2014-02-16 17:54:57,716 : DEBUG ::: Error occured on line 256 in file /home/konrad/.venv/sub_rosa/main/views.py
2014-02-16 17:54:57,716 : DEBUG ::: Message: Error writing to database
2014-02-16 17:54:57,716 : DEBUG ::: Message: Error writing to database
2014-02-16 17:54:57,716 : DEBUG ::: Message: Error writing to database
2014-02-16 17:54:57,716 : DEBUG ::: Details:
2014-02-16 17:54:57,716 : DEBUG ::: Details:
2014-02-16 17:54:57,716 : DEBUG ::: Details:
2014-02-16 17:54:57,716 : DEBUG ::: --------
2014-02-16 17:54:57,716 : DEBUG ::: --------
2014-02-16 17:54:57,716 : DEBUG ::: --------
2014-02-16 17:54:57,717 : DEBUG ::: Type: <class 'sqlalchemy.exc.IntegrityError'>
2014-02-16 17:54:57,717 : DEBUG ::: Type: <class 'sqlalchemy.exc.IntegrityError'>
2014-02-16 17:54:57,717 : DEBUG ::: Type: <class 'sqlalchemy.exc.IntegrityError'>
2014-02-16 17:54:57,717 : DEBUG ::: Value: (IntegrityError) UNIQUE constraint failed: user_images.filename u'INSERT INTO user_images (filename, showcase, description, is_vertical, gallery, owner_id) VALUES (?, ?, ?, ?, ?, ?)' (u'konrad/mount-vesuvius-in-eruption-1817.jpg', u'konrad/showcase/mount-vesuvius-in-eruption-1817.showcase.jpg', None, 0, 0, 1)
2014-02-16 17:54:57,717 : DEBUG ::: Value: (IntegrityError) UNIQUE constraint failed: user_images.filename u'INSERT INTO user_images (filename, showcase, description, is_vertical, gallery, owner_id) VALUES (?, ?, ?, ?, ?, ?)' (u'konrad/mount-vesuvius-in-eruption-1817.jpg', u'konrad/showcase/mount-vesuvius-in-eruption-1817.showcase.jpg', None, 0, 0, 1)
2014-02-16 17:54:57,717 : DEBUG ::: Value: (IntegrityError) UNIQUE constraint failed: user_images.filename u'INSERT INTO user_images (filename, showcase, description, is_vertical, gallery, owner_id) VALUES (?, ?, ?, ?, ?, ?)' (u'konrad/mount-vesuvius-in-eruption-1817.jpg', u'konrad/showcase/mount-vesuvius-in-eruption-1817.showcase.jpg', None, 0, 0, 1)
2014-02-16 17:54:57,717 : DEBUG ::: Traceback: <traceback object at 0x7fc2cc08d950>
2014-02-16 17:54:57,717 : DEBUG ::: Traceback: <traceback object at 0x7fc2cc08d950>
2014-02-16 17:54:57,717 : DEBUG ::: Traceback: <traceback object at 0x7fc2cc08d950>
2014-02-16 20:12:35,940 : DEBUG ::: ==============================
2014-02-16 20:12:35,940 : DEBUG ::: Error occured on line 256 in file /home/konrad/.venv/sub_rosa/main/views.py
2014-02-16 20:12:35,940 : DEBUG ::: Message: Error writing to database
2014-02-16 20:12:35,940 : DEBUG ::: Details:
2014-02-16 20:12:35,940 : DEBUG ::: --------
2014-02-16 20:12:35,941 : DEBUG ::: Type: <class 'sqlalchemy.exc.IntegrityError'>
2014-02-16 20:12:35,941 : DEBUG ::: Value: (IntegrityError) UNIQUE constraint failed: user_images.filename u'INSERT INTO user_images (filename, showcase, description, is_vertical, gallery, owner_id) VALUES (?, ?, ?, ?, ?, ?)' (u'konrad/Wreckers_Coast_of_Northumberland_Joseph_Mallord_William_Turner.jpeg', u'konrad/showcase/Wreckers_Coast_of_Northumberland_Joseph_Mallord_William_Turner.showcase.jpeg', None, 0, 0, 1)
2014-02-16 20:12:35,941 : DEBUG ::: Traceback: <traceback object at 0x7ffc6972a1b8>
2014-02-16 20:14:07,363 : DEBUG ::: ==============================
2014-02-16 20:14:07,363 : DEBUG ::: ==============================
2014-02-16 20:14:07,363 : DEBUG ::: Error occured on line 256 in file /home/konrad/.venv/sub_rosa/main/views.py
2014-02-16 20:14:07,363 : DEBUG ::: Error occured on line 256 in file /home/konrad/.venv/sub_rosa/main/views.py
2014-02-16 20:14:07,363 : DEBUG ::: Message: Error writing to database
2014-02-16 20:14:07,363 : DEBUG ::: Message: Error writing to database
2014-02-16 20:14:07,363 : DEBUG ::: Details:
2014-02-16 20:14:07,363 : DEBUG ::: Details:
2014-02-16 20:14:07,363 : DEBUG ::: --------
2014-02-16 20:14:07,363 : DEBUG ::: --------
2014-02-16 20:14:07,363 : DEBUG ::: Type: <class 'sqlalchemy.exc.IntegrityError'>
2014-02-16 20:14:07,363 : DEBUG ::: Type: <class 'sqlalchemy.exc.IntegrityError'>
2014-02-16 20:14:07,363 : DEBUG ::: Value: (IntegrityError) UNIQUE constraint failed: user_images.filename u'INSERT INTO user_images (filename, showcase, description, is_vertical, gallery, owner_id) VALUES (?, ?, ?, ?, ?, ?)' (u'konrad/Joseph-Mallord-William-Turner-Paintings-Snow-Storm-Hannibal-and-his-Army-Crossing-the-Alps-1812.jpg', u'konrad/showcase/Joseph-Mallord-William-Turner-Paintings-Snow-Storm-Hannibal-and-his-Army-Crossing-the-Alps-1812.showcase.jpg', None, 0, 0, 1)
2014-02-16 20:14:07,363 : DEBUG ::: Value: (IntegrityError) UNIQUE constraint failed: user_images.filename u'INSERT INTO user_images (filename, showcase, description, is_vertical, gallery, owner_id) VALUES (?, ?, ?, ?, ?, ?)' (u'konrad/Joseph-Mallord-William-Turner-Paintings-Snow-Storm-Hannibal-and-his-Army-Crossing-the-Alps-1812.jpg', u'konrad/showcase/Joseph-Mallord-William-Turner-Paintings-Snow-Storm-Hannibal-and-his-Army-Crossing-the-Alps-1812.showcase.jpg', None, 0, 0, 1)
2014-02-16 20:14:07,363 : DEBUG ::: Traceback: <traceback object at 0x7ffc6972e9e0>
2014-02-16 20:14:07,363 : DEBUG ::: Traceback: <traceback object at 0x7ffc6972e9e0>
2014-02-16 20:14:07,740 : DEBUG ::: ==============================
2014-02-16 20:14:07,740 : DEBUG ::: ==============================
2014-02-16 20:14:07,740 : DEBUG ::: ==============================
2014-02-16 20:14:07,740 : DEBUG ::: Error occured on line 256 in file /home/konrad/.venv/sub_rosa/main/views.py
2014-02-16 20:14:07,740 : DEBUG ::: Error occured on line 256 in file /home/konrad/.venv/sub_rosa/main/views.py
2014-02-16 20:14:07,740 : DEBUG ::: Error occured on line 256 in file /home/konrad/.venv/sub_rosa/main/views.py
2014-02-16 20:14:07,740 : DEBUG ::: Message: Error writing to database
2014-02-16 20:14:07,740 : DEBUG ::: Message: Error writing to database
2014-02-16 20:14:07,740 : DEBUG ::: Message: Error writing to database
2014-02-16 20:14:07,740 : DEBUG ::: Details:
2014-02-16 20:14:07,740 : DEBUG ::: Details:
2014-02-16 20:14:07,740 : DEBUG ::: Details:
2014-02-16 20:14:07,740 : DEBUG ::: --------
2014-02-16 20:14:07,740 : DEBUG ::: --------
2014-02-16 20:14:07,740 : DEBUG ::: --------
2014-02-16 20:14:07,740 : DEBUG ::: Type: <class 'sqlalchemy.exc.IntegrityError'>
2014-02-16 20:14:07,740 : DEBUG ::: Type: <class 'sqlalchemy.exc.IntegrityError'>
2014-02-16 20:14:07,740 : DEBUG ::: Type: <class 'sqlalchemy.exc.IntegrityError'>
2014-02-16 20:14:07,741 : DEBUG ::: Value: (IntegrityError) UNIQUE constraint failed: user_images.filename u'INSERT INTO user_images (filename, showcase, description, is_vertical, gallery, owner_id) VALUES (?, ?, ?, ?, ?, ?)' (u'konrad/Joseph-Mallord-William-Turner-Paintings-Snow-Storm-Hannibal-and-his-Army-Crossing-the-Alps-1812.jpg', u'konrad/showcase/Joseph-Mallord-William-Turner-Paintings-Snow-Storm-Hannibal-and-his-Army-Crossing-the-Alps-1812.showcase.jpg', None, 0, 0, 1)
2014-02-16 20:14:07,741 : DEBUG ::: Value: (IntegrityError) UNIQUE constraint failed: user_images.filename u'INSERT INTO user_images (filename, showcase, description, is_vertical, gallery, owner_id) VALUES (?, ?, ?, ?, ?, ?)' (u'konrad/Joseph-Mallord-William-Turner-Paintings-Snow-Storm-Hannibal-and-his-Army-Crossing-the-Alps-1812.jpg', u'konrad/showcase/Joseph-Mallord-William-Turner-Paintings-Snow-Storm-Hannibal-and-his-Army-Crossing-the-Alps-1812.showcase.jpg', None, 0, 0, 1)
2014-02-16 20:14:07,741 : DEBUG ::: Value: (IntegrityError) UNIQUE constraint failed: user_images.filename u'INSERT INTO user_images (filename, showcase, description, is_vertical, gallery, owner_id) VALUES (?, ?, ?, ?, ?, ?)' (u'konrad/Joseph-Mallord-William-Turner-Paintings-Snow-Storm-Hannibal-and-his-Army-Crossing-the-Alps-1812.jpg', u'konrad/showcase/Joseph-Mallord-William-Turner-Paintings-Snow-Storm-Hannibal-and-his-Army-Crossing-the-Alps-1812.showcase.jpg', None, 0, 0, 1)
2014-02-16 20:14:07,741 : DEBUG ::: Traceback: <traceback object at 0x7ffc6973b0e0>
2014-02-16 20:14:07,741 : DEBUG ::: Traceback: <traceback object at 0x7ffc6973b0e0>
2014-02-16 20:14:07,741 : DEBUG ::: Traceback: <traceback object at 0x7ffc6973b0e0>
